Workbook

Sheet BOV Summary
A2: BROKER OPINION OF VALUE
A3: Oak Shadows Mobile Home Park | San Andreas, CA | 105 Units | Confidential
A4: Prepared by: Northmarq | March 2026
B6: ESTIMATED VALUE | E6: STABILIZED NOI | J6: =B7 -> 14438854
B7: =F25 -> 14438854 | E7: ='Income Statement'!E63 -> 721942.69
E8: Annual Net Operating Income
B10: PROPERTY OVERVIEW
B11: Property Name | C11: Oak Shadows Mobile Home Park | E11: Total Units | F11: 105
B12: Property Type | C12: Manufactured Housing Community | E12: Occupied Units | F12: 105
B13: Location | C13: 1330 Calaveritas Rd, San Andreas, CA 95249 | E13: Occupancy Rate | F13: =F12/F11 -> 1
B14: Lot Rent Range | C14: $844-$864 | E14: Avg. Lot Rent ($/space/mo) | F14: ='Income Statement'!E7/F11/12 -> 855.06667
B15: Management | C15: Keith Management | E15: Year of Analysis | F15: 2026
B17: VALUATION SUMMARY
B18: Gross Potential Rent (2026 Normalized) | F18: ='Income Statement'!E7 -> 1077384
B19: Total Utility Income (2026 Normalized) | F19: ='Income Statement'!E20 -> 441499.48
B20: Effective Gross Income (2026 Normalized) | F20: ='Income Statement'!E23 -> 1484853
B21: Total Operating Expenses (2026 Normalized) | F21: ='Income Statement'!E61 -> 762910.33
B22: Net Operating Income — Stabilized NOI | F22: ='Income Statement'!E63 -> 721942.69
B24: Cap Rate Applied (Broker Selected) | F24: 0.05
B25: Estimated Value (NOI / Cap Rate) | F25: =F22/F24 -> 14438854
B26: Price Per Unit | F26: =F25/105 -> 137512.89
B29: MARKET COMPARABLES SUMMARY
B30: Comp Avg Sale Price | C30: ='Sales Comps'!D17 | E30: Comp Avg Lot Rent | F30: ='Rent Comps'!E17
B31: Comp Avg Price / Space | C31: =IFERROR('Sales Comps'!D17/'Sales Comps'!F17,"") | E31: Comp Avg Occupancy | F31: ='Rent Comps'!I17
B32: Comp Avg Cap Rate | C32: ='Sales Comps'!G17 | E32: Subject Avg Lot Rent | F32: ='Income Statement'!C7/105/12 -> 811.84102
B33: Sales Comp Count | C33: ='Sales Comps'!D18 -> 0 | E33: Rent Comp Count | F33: ='Rent Comps'!E18 -> 0
B34: Subject Price / Space | C34: =F26 -> 137512.89 | E34: Subject vs. Comp Lot Rent | F34: =IFERROR('Income Statement'!C7/105/12-'Rent Comps'!E17,"")
B35: Subject Cap Rate (BOV) | C35: =F24 -> 0.05 | E35: Subject 2026 Lot Rent | F35: ='Income Statement'!D7/105/12 -> 855.06667
B36: ↗ Enter comps directly in the 'Sales Comps' and 'Rent Comps' tabs — averages update automatically on this page
B42: DISCLAIMER: This Broker Opinion of Value (BOV) is prepared for informational purposes only and does not constitute an appraisal, guarantee of value, or offer to sell. Actual market value may differ. All information is derived from owner-provided financials and current market conditions as of March 2026.

Sheet Income Statement
A2: INCOME & EXPENSE STATEMENT
A3: Oak Shadows MHP | January – December 2025 | Accrual Basis
A4: Northmarq | March 2026
B5: LINE ITEM | C5: ACTUAL 2025 | D5: 2026 w/ rent Increase | E5: 2026 Normalized (Adjustable) | F5: Normalization Notes | H5: NORMALIZATION ASSUMPTIONS
B6: INCOME | E6: ← Blue cells = adjustable inputs | F6: ← Explain any adjustments in the Normalized column | H6: Adjust inputs below — Normalized column updates automatically
B7: Lot Rent / Rental Income | C7: 1022919.7 | D7: =89782*12 -> 1077384 | E7: =D7 -> 1077384 | H7: Property Tax Inputs
B8: Storage Fees | C8: 2175 | D8: =C8 -> 2175 | E8: =D8 -> 2175 | H8: Estimated Value (from BOV Summary) | I8: ='BOV Summary'!F25 -> 14438854 | J8: Linked to BOV Summary estimated value (iterative calc enabled). Excel recalculates ~100x until NOI & value converge.
B9: Application & NSF Fees | C9: 425 | D9: =C9 -> 425 | E9: =D9 -> 425 | H9: Property Tax Rate (%) | I9: 0.012 | J9: Adjust rate here — E48 updates automatically
B10: Late Fees | C10: 30 | D10: =C10 -> 30 | E10: =D10 -> 30 | H10: → Calculated Annual Property Tax | I10: =I8*I9 -> 173266.25 | J10: ← Converges dynamically: Value → Tax → NOI → Value. Iterative calc resolves this in ~3-5 passes.
B11: Concession Credits | C11: -6935.7 | D11: =C11 -> -6935.7 | E11: =D11 -> -6935.7
B12: Cable Income | C12: 1996.76 | D12: =C12 -> 1996.76 | E12: =D12 -> 1996.76 | H12: Other Normalization Inputs
B13: Misc Income | C13: 600 | D13: =C13 -> 600 | E13: =D13 -> 600 | H13: Vacancy & Credit Loss Rate (%) | I13: 0.03 | J13: Applied to Lot Rent in Normalized column (row 22)
B14: Utility Income Billed to Tenants
B15: Gas & Propane Billed | C15: 96917.72 | D15: =C15 -> 96917.72 | E15: =D15 -> 96917.72
B16: Water Billed | C16: 28005.67 | D16: =C16 -> 28005.67 | E16: =D16 -> 28005.67
B17: Sewer Billed | C17: 96379.01 | D17: =C17 -> 96379.01 | E17: =D17 -> 96379.01
B18: Garbage Billed | C18: 64778.75 | D18: =C18 -> 64778.75 | E18: =D18 -> 64778.75
B19: Electric Billed | C19: 155418.33 | D19: =C19 -> 155418.33 | E19: =D19 -> 155418.33
B20: Total Utility Income | C20: =SUM(C15:C19) -> 441499.48 | D20: =D15+D16+D17+D18+D19 -> 441499.48 | E20: =E15+E16+E17+E18+E19 -> 441499.48
B21: Vacancy & Credit Loss | C21: - | D21: - | E21: 0.03 | F21: Vacancy rate applied to Lot Rent; adjust % in col E → updates EGI automatically
B23: EFFECTIVE GROSS INCOME (EGI) | C23: =SUM(C7:C13)+C20 -> 1462710.2 | D23: =SUM(D7:D13)+D20 -> 1517174.5 | E23: =SUM(E7:E13)+E20-(E21*E7) -> 1484853
B25: OPERATING EXPENSES
B26: Utility Expenses (Pass-Through)
B27: Gas & Propane Cost | C27: 92358.36 | D27: =C27 -> 92358.36 | E27: =D27 -> 92358.36
B28: Water Cost | C28: 32070.37 | D28: =C28 -> 32070.37 | E28: =D28 -> 32070.37
B29: Sewer Cost | C29: 97860 | D29: =C29 -> 97860 | E29: =D29 -> 97860
B30: Electric Cost | C30: 174906.94 | D30: =C30 -> 174906.94 | E30: =D30 -> 174906.94
B31: Garbage Cost | C31: 39616.82 | D31: =C31 -> 39616.82 | E31: =D31 -> 39616.82
B32: Total Utility Expenses | C32: =SUM(C27:C31) -> 436812.49 | D32: =D26+D27+D28+D29+D30 -> 397195.67 | E32: =E26+E27+E28+E29+E30 -> 397195.67
B34: Advertising | C34: 1181.58 | D34: =C34 -> 1181.58 | E34: =D34 -> 1181.58
B35: Travel & Auto | C35: 1597.71 | D35: =C35 -> 1597.71 | E35: =D35 -> 1597.71
B36: Pest Control | C36: 2148.9 | D36: =C36 -> 2148.9 | E36: =D36 -> 2148.9
B37: Landscaping | C37: 1813.77 | D37: =C37 -> 1813.77 | E37: =D37 -> 1813.77
B38: Building Insurance | C38: 34011.35 | D38: =C38 -> 34011.35 | E38: 50000 | F38: Est increase
B39: Manager Insurance | C39: 2428.15 | D39: =C39 -> 2428.15 | E39: =D39 -> 2428.15
B40: Legal Fees (recurring) | C40: 690 | D40: =C40 -> 690 | E40: =D40 -> 690
B41: Interest Expense (operating) | C41: 297.16 | D41: =C41 -> 297.16 | E41: =D41 -> 297.16
B42: Pool Expense | C42: 2730.6 | D42: =C42 -> 2730.6 | E42: =D42 -> 2730.6
B43: Maintenance | C43: 5581.16 | D43: =C43 -> 5581.16 | E43: =D43 -> 5581.16
B44: Cleaning | C44: 350 | D44: =C44 -> 350 | E44: =D44 -> 350
...

Sheet Sales Comps
B2: SALES COMPARABLES
B3: Oak Shadows MHP | Enter comps manually — all blue cells are inputs | March 2026
B5: Enter up to 10 sales comparables below. Blue cells = manual inputs. Leave rows blank if unused. Cap rate optional if not disclosed.
B6: Park Name | C6: Address / City, State | D6: Sale Price | E6: Sale Date | F6: # Units (Spaces) | G6: Cap Rate (if known) | H6: Utility Structure | I6: Lot Rent (Avg $/mo) | J6: Distance from Subject | K6: Notes
B17: AVERAGES (excl. blank rows) | D17: =IFERROR(AVERAGEIF(D7:D16,">0",D7:D16),"") | F17: =IFERROR(AVERAGEIF(F7:F16,">0",F7:F16),"") | G17: =IFERROR(AVERAGEIF(G7:G16,">0",G7:G16),"") | I17: =IFERROR(AVERAGEIF(I7:I16,">0",I7:I16),"")
B18: Comp Count | D18: =COUNTIF(D7:D16,">0") -> 0
B20: Utility Structure options: 'Sub-metered' | 'Master-metered' | 'Tenant-paid' | 'Owner-paid' | 'Partial' | 'N/A'

Sheet Rent Comps
B2: RENT COMPARABLES
B3: Oak Shadows MHP | Enter rent comps manually — all blue cells are inputs | March 2026
B5: Enter up to 10 rent comparables below. Blue cells = manual inputs. Leave rows blank if unused.
B6: Park Name | C6: Address / City, State | D6: # Units (Spaces) | E6: Avg Lot Rent ($/mo) | F6: Min Lot Rent ($/mo) | G6: Max Lot Rent ($/mo) | H6: Utility Structure | I6: Occupancy (%) | J6: Distance from Subject
B17: AVERAGES (excl. blank rows) | D17: =IFERROR(AVERAGEIF(D7:D16,">0",D7:D16),"") | E17: =IFERROR(AVERAGEIF(E7:E16,">0",E7:E16),"") | F17: =IFERROR(AVERAGEIF(F7:F16,">0",F7:F16),"") | G17: =IFERROR(AVERAGEIF(G7:G16,">0",G7:G16),"") | I17: =IFERROR(AVERAGEIF(I7:I16,">0",I7:I16),"")
B18: Comp Count | E18: =COUNTIF(E7:E16,">0") -> 0
B20: Utility Structure options: 'Sub-metered' | 'Master-metered' | 'Tenant-paid' | 'Owner-paid' | 'Partial' | 'N/A'

Sheet 5-Year Cash Flow
A2: 5-YEAR PRO FORMA CASH FLOW
A3: Oak Shadows MHP | Projected 2026 – 2030 | Capital Markets as of March 2026
A4: Northmarq | March 2026
B5: KEY ASSUMPTIONS
B6: Rent Growth Rate (Annual) | C6: 0.035
B7: Expense Growth Rate | C7: 0.02
B8: Vacancy / Credit Loss | C8: 0.03
B9: Interest Rate (Financing) | C9: 0.0525
B10: LTV | C10: 0.65
B11: Exit Cap Rate (Yr 5) | C11: 0.05
B12: Purchase Price (BOV Estimate) | C12: ='BOV Summary'!F25 -> 14438854 | D12: ← Links to BOV Summary estimated value; override with offer price if needed
B13: Note: Interest rate reflects Fannie Mae/Freddie Mac spreads (+2.35%) over 10-yr Treasury (~4.26%) as of March 2026. Rent growth based on Midwest MHP market averages.
B14: LINE ITEM | C14: 2026 (Yr 1) | D14: 2027 (Yr 2) | E14: 2028 (Yr 3) | F14: 2029 (Yr 4) | G14: 2030 (Yr 5)
B16: INCOME
B17: Gross Potential Rental Income | C17: ='Income Statement'!E7 -> 1077384 | D17: =C17*(1+$C$6) -> 1115092.4 | E17: =D17*(1+$C$6) -> 1154120.7 | F17: =E17*(1+$C$6) -> 1194514.9 | G17: =F17*(1+$C$6) -> 1236322.9
B18: Other Income (fees, cable, misc) | C18: =SUM('Income Statement'!E8:E13)-'Income Statement'!E10 -> -1738.94 | D18: =C18*(1+$C$6) -> -1799.8029 | E18: =D18*(1+$C$6) -> -1862.796 | F18: =E18*(1+$C$6) -> -1927.9939 | G18: =F18*(1+$C$6) -> -1995.4736
B19: Utility Income (gross billed) | C19: ='Income Statement'!E20 -> 441499.48 | D19: =C19*(1+$C$6) -> 456951.96 | E19: =D19*(1+$C$6) -> 472945.28 | F19: =E19*(1+$C$6) -> 489498.37 | G19: =F19*(1+$C$6) -> 506630.81
B20: Vacancy & Credit Loss | C20: =-C17*$C$8 -> -32321.52 | D20: =-D17*$C$8 -> -33452.773 | E20: =-E17*$C$8 -> -34623.62 | F20: =-F17*$C$8 -> -35835.447 | G20: =-G17*$C$8 -> -37089.688
B21: EFFECTIVE GROSS INCOME | C21: =SUM(C17:C20) -> 1484823 | D21: =SUM(D17:D20) -> 1536791.8 | E21: =SUM(E17:E20) -> 1590579.5 | F21: =SUM(F17:F20) -> 1646249.8 | G21: =SUM(G17:G20) -> 1703868.6
B23: OPERATING EXPENSES
B24: Total Operating Expenses | C24: ='Income Statement'!E61 -> 762910.33 | D24: =C24*(1+$C$7) -> 778168.53 | E24: =D24*(1+$C$7) -> 793731.9 | F24: =E24*(1+$C$7) -> 809606.54 | G24: =F24*(1+$C$7) -> 825798.67
B26: TOTAL OPERATING EXPENSES | C26: =C24 -> 762910.33 | D26: =D24 -> 778168.53 | E26: =E24 -> 793731.9 | F26: =F24 -> 809606.54 | G26: =G24 -> 825798.67
B28: NET OPERATING INCOME (NOI) | C28: =C21-C26 -> 721912.69 | D28: =D21-D26 -> 758623.29 | E28: =E21-E26 -> 796847.64 | F28: =F21-F26 -> 836643.28 | G28: =G21-G26 -> 878069.89
B30: DEBT SERVICE (65% LTV / 30-yr Amort)
B31: Loan Amount (65% LTV) | C31: ='BOV Summary'!F25*$C$10 -> 9385255 | D31: =C31 -> 9385255 | E31: =C31 -> 9385255 | F31: =C31 -> 9385255 | G31: =C31 -> 9385255
B32: Annual Debt Service (P&I) | C32: =-PMT($C$9/12,360,C31)*12 -> 621908.71 | D32: =-PMT($C$9/12,360,C31)*12 -> 621908.71 | E32: =-PMT($C$9/12,360,C31)*12 -> 621908.71 | F32: =-PMT($C$9/12,360,C31)*12 -> 621908.71 | G32: =-PMT($C$9/12,360,C31)*12 -> 621908.71
B33: CASH FLOW AFTER DEBT SERVICE | C33: =C28-C32 -> 100003.99 | D33: =D28-D32 -> 136714.58 | E33: =E28-E32 -> 174938.93 | F33: =F28-F32 -> 214734.57 | G33: =G28-G32 -> 256161.19
B34: Cash-on-Cash Return | C34: =C33/(C12-C31) -> 0.019788667 | D34: =D33/(C12-C31) -> 0.027052916 | E34: =E33/(C12-C31) -> 0.034616702 | F34: =F33/(C12-C31) -> 0.042491417 | G34: =G33/(C12-C31) -> 0.050688864
B36: YEAR 5 DISPOSITION
B37: Year 5 NOI | G37: =G28 -> 878069.89
B38: Exit Cap Rate | G38: =$C$11 -> 0.05
B39: Estimated Sale Price | G39: =G37/G38 -> 17561398
B40: Less: Loan Balance (est) | G40: =G31*0.93 -> 8728287.2
B41: Net Sale Proceeds | G41: =G39-G40 -> 8833110.7
B43: 5-YEAR IRR ANALYSIS
B44: Levered IRR based on equity invested (purchase price − loan). Year 0 = initial equity outflow. Year 5 includes cash flow + net sale proceeds.
C45: Year 0 (Acquisition) | D45: Year 1 2026 | E45: Year 2 2027 | F45: Year 3 2028 | G45: Year 4 2029 | H45: Year 5 2030
B46: Initial Equity / Cash Flows | C46: =-(C12-C31) -> -5053598.9 | D46: =C33 -> 100003.99 | E46: =D33 -> 136714.58 | F46: =E33 -> 174938.93 | G46: =F33 -> 214734.57 | H46: =G33+G41 -> 9089271.9
B47: 5-YEAR LEVERED IRR | F47: =IRR(C46:H46) -> 0.14490562
B48: Equity Multiple (MOIC) | F48: =(SUM(D46:H46)-C46)/(-C46) -> 2.9225238
...
